[2023-07-13T13:09:30.725+0000] {taskinstance.py:1103} INFO - Dependencies all met for dep_context=non-requeueable deps ti=<TaskInstance: process_sales_13.extract_data_from_api manual__2023-07-13T13:06:50.414120+00:00 [queued]>
[2023-07-13T13:09:30.735+0000] {taskinstance.py:1103} INFO - Dependencies all met for dep_context=requeueable deps ti=<TaskInstance: process_sales_13.extract_data_from_api manual__2023-07-13T13:06:50.414120+00:00 [queued]>
[2023-07-13T13:09:30.735+0000] {taskinstance.py:1308} INFO - Starting attempt 2 of 2
[2023-07-13T13:09:30.750+0000] {taskinstance.py:1327} INFO - Executing <Task(PythonOperator): extract_data_from_api> on 2023-07-13 13:06:50.414120+00:00
[2023-07-13T13:09:30.754+0000] {standard_task_runner.py:57} INFO - Started process 4352 to run task
[2023-07-13T13:09:30.758+0000] {standard_task_runner.py:84} INFO - Running: ['***', 'tasks', 'run', 'process_sales_13', 'extract_data_from_api', 'manual__2023-07-13T13:06:50.414120+00:00', '--job-id', '193', '--raw', '--subdir', 'DAGS_FOLDER/process_sales_13.py', '--cfg-path', '/tmp/tmpbzrj2zqd']
[2023-07-13T13:09:30.759+0000] {standard_task_runner.py:85} INFO - Job 193: Subtask extract_data_from_api
[2023-07-13T13:09:30.808+0000] {task_command.py:410} INFO - Running <TaskInstance: process_sales_13.extract_data_from_api manual__2023-07-13T13:06:50.414120+00:00 [running]> on host b58a2d5f4d18
[2023-07-13T13:09:30.894+0000] {taskinstance.py:1547} INFO - Exporting env vars: AIRFLOW_CTX_DAG_OWNER='***' AIRFLOW_CTX_DAG_ID='process_sales_13' AIRFLOW_CTX_TASK_ID='extract_data_from_api' AIRFLOW_CTX_EXECUTION_DATE='2023-07-13T13:06:50.414120+00:00' AIRFLOW_CTX_TRY_NUMBER='2' AIRFLOW_CTX_DAG_RUN_ID='manual__2023-07-13T13:06:50.414120+00:00'
[2023-07-13T13:09:30.896+0000] {taskinstance.py:1824} ERROR - Task failed with exception
Traceback (most recent call last):
  File "/home/airflow/.local/lib/python3.7/site-packages/airflow/operators/python.py", line 181, in execute
    return_value = self.execute_callable()
  File "/home/airflow/.local/lib/python3.7/site-packages/airflow/operators/python.py", line 198, in execute_callable
    return self.python_callable(*self.op_args, **self.op_kwargs)
TypeError: extract_data_from_api_task() takes 1 positional argument but 3 were given
[2023-07-13T13:09:30.905+0000] {taskinstance.py:1350} INFO - Marking task as FAILED. dag_id=process_sales_13, task_id=extract_data_from_api, execution_date=20230713T130650, start_date=20230713T130930, end_date=20230713T130930
[2023-07-13T13:09:30.916+0000] {standard_task_runner.py:109} ERROR - Failed to execute job 193 for task extract_data_from_api (extract_data_from_api_task() takes 1 positional argument but 3 were given; 4352)
[2023-07-13T13:09:30.930+0000] {local_task_job_runner.py:225} INFO - Task exited with return code 1
[2023-07-13T13:09:30.953+0000] {taskinstance.py:2653} INFO - 0 downstream tasks scheduled from follow-on schedule check
