[2023-07-13T13:09:32.985+0000] {taskinstance.py:1103} INFO - Dependencies all met for dep_context=non-requeueable deps ti=<TaskInstance: process_sales_13.extract_data_from_api manual__2023-07-13T13:09:31.629015+00:00 [queued]>
[2023-07-13T13:09:32.994+0000] {taskinstance.py:1103} INFO - Dependencies all met for dep_context=requeueable deps ti=<TaskInstance: process_sales_13.extract_data_from_api manual__2023-07-13T13:09:31.629015+00:00 [queued]>
[2023-07-13T13:09:32.995+0000] {taskinstance.py:1308} INFO - Starting attempt 1 of 1
[2023-07-13T13:09:33.009+0000] {taskinstance.py:1327} INFO - Executing <Task(PythonOperator): extract_data_from_api> on 2023-07-13 13:09:31.629015+00:00
[2023-07-13T13:09:33.014+0000] {standard_task_runner.py:57} INFO - Started process 4355 to run task
[2023-07-13T13:09:33.017+0000] {standard_task_runner.py:84} INFO - Running: ['***', 'tasks', 'run', 'process_sales_13', 'extract_data_from_api', 'manual__2023-07-13T13:09:31.629015+00:00', '--job-id', '194', '--raw', '--subdir', 'DAGS_FOLDER/process_sales_13.py', '--cfg-path', '/tmp/tmpsajc8qxe']
[2023-07-13T13:09:33.018+0000] {standard_task_runner.py:85} INFO - Job 194: Subtask extract_data_from_api
[2023-07-13T13:09:33.061+0000] {task_command.py:410} INFO - Running <TaskInstance: process_sales_13.extract_data_from_api manual__2023-07-13T13:09:31.629015+00:00 [running]> on host b58a2d5f4d18
[2023-07-13T13:09:33.150+0000] {taskinstance.py:1547} INFO - Exporting env vars: AIRFLOW_CTX_DAG_OWNER='***' AIRFLOW_CTX_DAG_ID='process_sales_13' AIRFLOW_CTX_TASK_ID='extract_data_from_api' AIRFLOW_CTX_EXECUTION_DATE='2023-07-13T13:09:31.629015+00:00' AIRFLOW_CTX_TRY_NUMBER='1' AIRFLOW_CTX_DAG_RUN_ID='manual__2023-07-13T13:09:31.629015+00:00'
[2023-07-13T13:09:33.152+0000] {taskinstance.py:1824} ERROR - Task failed with exception
Traceback (most recent call last):
  File "/home/airflow/.local/lib/python3.7/site-packages/airflow/operators/python.py", line 181, in execute
    return_value = self.execute_callable()
  File "/home/airflow/.local/lib/python3.7/site-packages/airflow/operators/python.py", line 198, in execute_callable
    return self.python_callable(*self.op_args, **self.op_kwargs)
TypeError: extract_data_from_api_task() takes 1 positional argument but 3 were given
[2023-07-13T13:09:33.161+0000] {taskinstance.py:1350} INFO - Marking task as FAILED. dag_id=process_sales_13, task_id=extract_data_from_api, execution_date=20230713T130931, start_date=20230713T130932, end_date=20230713T130933
[2023-07-13T13:09:33.173+0000] {standard_task_runner.py:109} ERROR - Failed to execute job 194 for task extract_data_from_api (extract_data_from_api_task() takes 1 positional argument but 3 were given; 4355)
[2023-07-13T13:09:33.190+0000] {local_task_job_runner.py:225} INFO - Task exited with return code 1
[2023-07-13T13:09:33.212+0000] {taskinstance.py:2653} INFO - 0 downstream tasks scheduled from follow-on schedule check
